# 1. try - catch
c++ 通过 try - catch 捕获处理异常，基本语法为：
```cpp
try{
    // 可能抛出异常的语句
}catch(exceptionType variable){
    // 处理异常的语句
}
```

`demo`
```cpp
int main() {
  std::vector<int>vec(10);
  try{
    vec.at(11);
    std::cout << "here\n";
  }catch(std::exception& e){
    std::cout << e.what();
  }
}
```
`注意，检测到异常后程序的执行流会发生跳转，从异常点跳转到 catch 所在的位置，位于异常点之后的、并且在当前 try 块内的语句就都不会再执行了；`
`即使 catch 语句成功地处理了错误，程序的执行流也不会再回退到异常点，所以这些语句永远都没有执行的机会了，即 “std::cout << "here\n";” 语句不会被执行。`

vector 的 `at` 接口传入的 index 超过了 vector 的元素个数，会抛出异常。

# 2. 标准异常
exception 类位于 <exception> 头文件中，它被声明为：
```cpp
class exception{
public:
    exception () throw();  //构造函数
    exception (const exception&) throw();  //拷贝构造函数
    exception& operator= (const exception&) throw();  //运算符重载
    virtual ~exception() throw();  //虚析构函数
    virtual const char* what() const throw();  //虚函数
}
```
`C++语言本身或者标准库抛出的异常都是 exception 的子类，称为标准异常（Standard Exception）。`

# 3. throw 抛出异常
throw 不仅可以抛出标准异常，也可以抛出`任意类型的异常`；
如抛出 int 类型的异常；
```cpp
int main() {
  std::vector<int>vec(10);
  try{
    throw int(1);
  }catch(int i){
    std::cout << "error int: " << i;
  }
}
```

# 4. 多级 catch
```cpp
try{
    //可能抛出异常的语句
}catch (exception_type_1 e){
    //处理异常的语句
}catch (exception_type_2 e){
    //处理异常的语句
}
//其他的catch
catch (exception_type_n e){
    //处理异常的语句
}
```
catch 没捕捉到匹配的异常类型，则抛出的异常就不会被处理

# noexcept 关键字
该关键字告诉编译器，函数中不会发生异常,这有利于编译器对程序做更多的优化。

如果在运行时，noexecpt函数向外抛出了异常（如果函数内部捕捉了异常并完成处理，这种情况不算抛出异常），程序会直接终止，调用std::terminate()函数，该函数内部会调用std::abort()终止程序。

[demo](./code/code_3)

`noexcept 不会导致函数重载`
```cpp
void f();
void f() noexcept; // error  
```

